Workbook

Sheet Léame
A1: Modelo de demanda y oferta de profesionales IoT en Los Ríos
A2: Borrador de trabajo para el proyecto de carrera de Ingeniería en Internet de las Cosas (UTEQ). Consulta de datos: 26-IX-2026.
A4: Qué es | B4: Un ejercicio de dimensionamiento con tres escenarios. Cruza empresas formales de Los Ríos (SRI e INEC) con supuestos de adopción y contratación de perfiles IoT, y lo compara con la oferta de graduados TIC.
A5: Qué NO es | B5: No es una proyección estadística. Ninguna fuente oficial publica la adopción de IoT por sector en Ecuador; esos porcentajes son supuestos de trabajo. Deben sustituirse con la encuesta a empleadores antes de presentar el proyecto al CES.
A6: Código de color | B6: Celdas amarillas = supuestos que usted puede cambiar. Celdas blancas = datos observados o fórmulas. Todo el modelo se recalcula al editar una celda amarilla.
A7: Hojas | B7: SRI_LosRios, INEC_LosRios y SENESCYT_TIC: datos observados. Supuestos: entradas. Demanda, Oferta, Brecha y Sensibilidad: cálculos.
A8: Horizonte | B8: Año base 2026. "4 años" = 2030 y "5 años" = 2031. Con ingreso en 2027 y 8 períodos, la primera promoción de la carrera se gradúa en 2031.
A9: Fuentes | B9: SRI: catastro RUC de Los Ríos (datos abiertos, actualizado el 1-IX-2026). INEC: Registro Estadístico de Empresas 2025, ENEMDU anual 2025, Censo 2022. SENESCYT: tableros de matrícula UEP y de títulos nacionales, y graduados TIC 2020 y 2021 de la Política de Transformación Digital 2025-2030 (MINTEL). UTEQ: informe de rendición de cuentas 2024.
A10: Límites de los datos | B10: El catastro RUC no trae tamaño de empresa; se usa "sociedad o persona natural obligada a llevar contabilidad" como aproximación de empresa formal. La matrícula y los títulos TIC de la SENESCYT se leyeron de sus tableros públicos (la base de datos abiertos no estaba disponible). La serie de títulos TIC por provincia y año no se pudo extraer completa: se usa 2024 y el acumulado; la oferta de graduados se estima a partir de la matrícula.
A11: Privacidad | B11: El catastro RUC incluye nombres de personas naturales. Este libro solo contiene conteos agregados.

Sheet SRI_LosRios
A1: Contribuyentes activos de Los Ríos (SRI, catastro RUC)
A2: Fuente: SRI, datos abiertos, "Registro Único de Contribuyentes / Los Ríos", actualizado el 1-IX-2026. Un RUC se cuenta una vez, con la CIIU de su establecimiento matriz.
A4: Grupo de actividad (CIIU Rev. 4.1) | B4: Sociedades activas | C4: Personas naturales obligadas a contabilidad | D4: Empresas formales | E4: Total RUC activos (incluye no obligados)
A5: G1 Agricultura, ganadería y silvicultura | B5: 851 | C5: 546 | D5: =B5+C5 -> 1397 | E5: 23498
A6: G2 Pesca y acuicultura | B6: 13 | C6: 1 | D6: =B6+C6 -> 14 | E6: 63
A7: G3 Alimentos y bebidas (agroindustria) | B7: 76 | C7: 17 | D7: =B7+C7 -> 93 | E7: 1709
A8: G4 Otras manufacturas | B8: 133 | C8: 30 | D8: =B8+C8 -> 163 | E8: 4004
A9: G5 Energía, agua y saneamiento | B9: 97 | C9: 0 | D9: =B9+C9 -> 97 | E9: 160
A10: G6 Transporte y almacenamiento | B10: 461 | C10: 46 | D10: =B10+C10 -> 507 | E10: 5907
A11: G7 Comercio al por mayor | B11: 661 | C11: 406 | D11: =B11+C11 -> 1067 | E11: 11779
A12: G8 Administración pública (GAD y entidades) | B12: 96 | C12: 0 | D12: =B12+C12 -> 96 | E12: 101
A13: G9 Proveedores tecnológicos (TIC, ingeniería, I+D) | B13: 229 | C13: 28 | D13: =B13+C13 -> 257 | E13: 1025
A14: G10 Construcción | B14: 570 | C14: 17 | D14: =B14+C14 -> 587 | E14: 2043
A15: G11 Salud | B15: 186 | C15: 15 | D15: =B15+C15 -> 201 | E15: 2178
A16: Otros sectores | B16: 1959 | C16: 519 | D16: =B16+C16 -> 2478 | E16: 59697
A17: Total | B17: =SUM(B5:B16) -> 5332 | C17: =SUM(C5:C16) -> 1625 | D17: =SUM(D5:D16) -> 6957 | E17: =SUM(E5:E16) -> 112164
A19: Empresas formales de las secciones O, P, Q y U (excluidas del universo "actividades productivas" del INEC)
A20: Administración pública (O), Enseñanza (P), Salud (Q) y otras (U) | D20: 416 | E20: O = 96, P = 119, Q = 201, U = 0 (cálculo propio sobre el catastro)
A22: Empresas formales de los grupos objetivo por cantón
A23: Cantón | B23: Empresas formales en grupos G1 a G9
A24: Quevedo | B24: 845
A25: Babahoyo | B25: 724
A26: Ventanas | B26: 353
A27: Buena Fe | B27: 316
A28: Vinces | B28: 247
A29: Valencia | B29: 197
A30: Pueblo Viejo | B30: 183
A31: Mocache | B31: 170
A32: Baba | B32: 149
A33: Montalvo | B33: 142
A34: Quinsaloma | B34: 104
A35: Urdaneta | B35: 101
A36: Palenque | B36: 70
A38: Altas de sociedades por año de inicio de actividades (RUC hoy activos)
A39: Año | B39: Sociedades activas que iniciaron ese año
A40: 2015 | B40: 156
A41: 2016 | B41: 151
A42: 2017 | B42: 220
A43: 2018 | B43: 171
A44: 2019 | B44: 263
...

Sheet INEC_LosRios
A1: Indicadores del INEC para Los Ríos
A2: Fuentes: REEM 2025, ENEMDU anual 2025, Censo de Población 2022.
A4: Indicador | B4: Los Ríos | C4: Nacional | D4: Fuente
A5: Empresas del universo REEM, 2025 | B5: 32993 | C5: 1204276 | D5: REEM 2025, cuadro 1.1.8
A6: Empresas con actividades productivas (ventas y empleo IESS), 2025 | B6: 1968 | C6: 86311 | D6: REEM 2025, cuadro 2.1.7
A7: Empleo registrado equivalente (IESS), 2025 | B7: 66742.5 | C7: 2921188.6 | D7: REEM 2025, cuadro 1.3.18
A8: Empleo adecuado o pleno, 2025 (%) | B8: 32.5 | C8: 37.1 | D8: ENEMDU anual 2025, tabla 5 y sección 1.4.1
A9: Subempleo, 2025 (%) | B9: 28.4 | D9: ENEMDU anual 2025, tabla 6
A10: Desempleo, 2025 (%) | B10: 1.7 | C10: 3.6 | D10: ENEMDU anual 2025, tabla 3 y sección 1.1
A11: Población, Censo 2022 | B11: 898652 | D11: INEC, Censo 2022 (Los Ríos, cuarta provincia más poblada)

Sheet SENESCYT_TIC
A1: Matrícula y títulos TIC (SENESCYT)
A2: Fuente: tableros públicos de la SENESCYT (Registro de matrícula UEP y Títulos nacionales), consultados el 26-IX-2026. Campo de estudio "Tecnologías de la información y la comunicación".
A4: Año | B4: Matrícula total UEP en Los Ríos | C4: Matrícula TIC UEP en Los Ríos | D4: % TIC
A5: 2016 | B5: 16655 | C5: 0 | D5: =C5/B5 -> 0
A6: 2017 | B6: 18660 | C6: 0 | D6: =C6/B6 -> 0
A7: 2018 | B7: 20885 | C7: 346 | D7: =C7/B7 -> 0.016566914
A8: 2019 | B8: 21207 | C8: 559 | D8: =C8/B8 -> 0.026359221
A9: 2020 | B9: 23580 | C9: 760 | D9: =C9/B9 -> 0.032230704
A10: 2021 | B10: 25581 | C10: 942 | D10: =C10/B10 -> 0.036824205
A11: 2022 | B11: 26653 | C11: 1005 | D11: =C11/B11 -> 0.037706825
A12: 2023 | B12: 27624 | C12: 1021 | D12: =C12/B12 -> 0.036960614
A13: Antes de 2018 el tablero no registra matrícula en el campo TIC en Los Ríos (efecto de la clasificación por campos vigente).
A15: Provincia | B15: Matrícula UEP 2022 | C15: Matrícula TIC UEP 2022 | D15: % TIC 2022 | E15: Títulos registrados 2024, todos | F15: Títulos TIC 2024, todos los niveles
A18: Los Ríos | B18: 26653 | C18: 1005 | D18: =C18/B18 -> 0.037706825 | E18: 3205 | F18: 69
A19: Guayas | B19: 207192 | C19: 9708 | D19: =C19/B19 -> 0.046855091 | E19: 38212 | F19: 1390
A20: Bolívar | B20: 7529 | C20: 183 | D20: =C20/B20 -> 0.024306017 | E20: 1265 | F20: 44
A21: Santo Domingo de los Tsáchilas | B21: 6752 | C21: 389 | D21: =C21/B21 -> 0.057612559 | E21: 1438 | F21: 80
A22: Nacional | B22: 792530 | C22: 33220 | D22: =C22/B22 -> 0.041916394 | E22: 123378 | F22: 4224
A24: Títulos TIC registrados entre 2013 y 2024 (acumulado, todos los niveles): Guayas 5.597; Los Ríos 518; Santo Domingo 319. Bolívar no aparece entre las 14 provincias con más títulos TIC.
A26: Año | B26: Títulos nacionales, todos los campos | C26: Títulos nacionales TIC
A27: 2013 | B27: 107971 | C27: 27
A28: 2014 | B28: 100161 | C28: 16
A29: 2015 | B29: 145723 | C29: 39
A30: 2016 | B30: 152544 | C30: 2
A31: 2017 | B31: 130748 | C31: 174
A32: 2018 | B32: 114504 | C32: 250
A33: 2019 | B33: 109933 | C33: 437
A34: 2020 | B34: 101048 | C34: 470
A35: 2021 | B35: 151518 | C35: 1797
A36: 2022 | B36: 186946 | C36: 4093
A37: 2023 | B37: 208299 | C37: 7663
A38: 2024 | B38: 123378 | C38: 4224
A40: Cautela: los títulos TIC de años anteriores a 2022 están subregistrados por la clasificación por campos; la Política del MINTEL cita 7.476 graduados TIC en 2021 frente a 1.797 en este tablero.

Sheet Supuestos
A1: Supuestos del modelo (celdas amarillas: editables)
A2: Sin fuente oficial. Son valores de trabajo para dimensionar; sustitúyalos con los resultados de la encuesta a empleadores.
A4: 1. Factor de empresas operativas
A5: Empresas INEC con ventas y empleo IESS (Los Ríos, 2025) | B5: =INEC_LosRios!B6 -> 1968
A6: Empresas formales SRI sin secciones O, P, Q y U | B6: =SRI_LosRios!D17-SRI_LosRios!D20 -> 6541
A7: Factor operativo calculado (INEC / SRI) | B7: =B5/B6 -> 0.30087143 | C7: Aproximado: las definiciones de INEC y SRI no coinciden exactamente.
A8: Factor operativo que usa el modelo (por defecto, el calculado, redondeado) | B8: =ROUND(B7,2) -> 0.3
A9: Factor operativo del sector público (los GAD operan) | B9: 1
A11: 2. Adopción: % de empresas operativas que contratan al menos un perfil IoT
A12: Grupo | B12: Conservador 2030 | C12: Conservador 2031 | D12: Base 2030 | E12: Base 2031 | F12: Optimista 2030 | G12: Optimista 2031
A13: G1 Agricultura, ganadería y silvicultura | B13: 0.01 | C13: 0.015 | D13: 0.025 | E13: 0.035 | F13: 0.05 | G13: 0.07
A14: G2 Pesca y acuicultura | B14: 0.02 | C14: 0.03 | D14: 0.05 | E14: 0.07 | F14: 0.1 | G14: 0.14
A15: G3 Alimentos y bebidas (agroindustria) | B15: 0.05 | C15: 0.07 | D15: 0.1 | E15: 0.14 | F15: 0.18 | G15: 0.24
A16: G4 Otras manufacturas | B16: 0.04 | C16: 0.05 | D16: 0.08 | E16: 0.11 | F16: 0.15 | G16: 0.2
A17: G5 Energía, agua y saneamiento | B17: 0.05 | C17: 0.07 | D17: 0.1 | E17: 0.14 | F17: 0.2 | G17: 0.26
A18: G6 Transporte y almacenamiento | B18: 0.02 | C18: 0.03 | D18: 0.05 | E18: 0.07 | F18: 0.1 | G18: 0.14
A19: G7 Comercio al por mayor | B19: 0.005 | C19: 0.0075 | D19: 0.015 | E19: 0.02 | F19: 0.03 | G19: 0.04
A20: G8 Administración pública (GAD y entidades) | B20: 0.1 | C20: 0.15 | D20: 0.25 | E20: 0.35 | F20: 0.4 | G20: 0.55
A21: G9 Proveedores tecnológicos (TIC, ingeniería, I+D) | B21: 0.15 | C21: 0.2 | D21: 0.3 | E21: 0.4 | F21: 0.5 | G21: 0.6
A22: Los porcentajes de la hoja de adopción son supuestos del equipo, sin fuente oficial.
A24: 3. Profesionales IoT por empresa que adopta
B25: Conservador | C25: Base | D25: Optimista
A26: Profesionales por empresa adoptante | B26: 1 | C26: 1.5 | D26: 2
A27: Profesionales IoT que ya trabajan en las empresas en 2026 | B27: 0
A29: 4. Oferta de graduados TIC en Los Ríos
A30: Matrícula TIC en IES de Los Ríos, 2023 (SENESCYT) | B30: =SENESCYT_TIC!C12 -> 1021
A31: Títulos TIC registrados en 2024 por IES de Los Ríos, todos los niveles (SENESCYT) | B31: =SENESCYT_TIC!F18 -> 69
B32: Oferta baja | C32: Oferta base | D32: Oferta alta
A33: Graduados TIC por año que salen de IES de Los Ríos | B33: =B31 -> 69 | C33: =ROUND(B30/B41*B39,0) -> 156 | D33: =ROUND(B30/B41,0) -> 255
A34: Baja: títulos TIC registrados en 2024. Base: matrícula TIC 2023 entre la duración media de la carrera, por la tasa de titulación. Alta: matrícula TIC 2023 entre la duración media, si todos se titularan.
A35: % de esos graduados con competencias útiles para IoT | B35: 0.02 | C35: 0.05 | D35: 0.1
A37: 5. La carrera propuesta
A38: Estudiantes por cohorte | B38: 40
A39: Tasa de titulación (UTEQ, cohorte 2018-2019) | B39: 0.6096
A40: Año del primer ingreso | B40: 2027
A41: Duración de la carrera en años | B41: 4

Sheet Demanda
A1: Demanda estimada de profesionales IoT en Los Ríos
A2: Puestos = empresas formales × factor operativo × % que adopta × profesionales por empresa. Es un stock acumulado al año indicado.
A4: Grupo | B4: Empresas formales (SRI) | C4: Factor operativo | D4: Empresas operativas | E4: Adoptan Cons. 2030 | F4: Adoptan Cons. 2031 | G4: Adoptan Base 2030 | H4: Adoptan Base 2031 | I4: Adoptan Opt. 2030 | J4: Adoptan Opt. 2031
A5: =SRI_LosRios!A5 -> G1 Agricultura, ganadería y silvicultura | B5: =SRI_LosRios!D5 -> 1397 | C5: =Supuestos!$B$8 -> 0.3 | D5: =B5*C5 -> 419.1 | E5: =D5*Supuestos!B13 -> 4.191 | F5: =D5*Supuestos!C13 -> 6.2865 | G5: =D5*Supuestos!D13 -> 10.4775 | H5: =D5*Supuestos!E13 -> 14.6685 | I5: =D5*Supuestos!F13 -> 20.955 | J5: =D5*Supuestos!G13 -> 29.337
A6: =SRI_LosRios!A6 -> G2 Pesca y acuicultura | B6: =SRI_LosRios!D6 -> 14 | C6: =Supuestos!$B$8 -> 0.3 | D6: =B6*C6 -> 4.2 | E6: =D6*Supuestos!B14 -> 0.084 | F6: =D6*Supuestos!C14 -> 0.126 | G6: =D6*Supuestos!D14 -> 0.21 | H6: =D6*Supuestos!E14 -> 0.294 | I6: =D6*Supuestos!F14 -> 0.42 | J6: =D6*Supuestos!G14 -> 0.588
A7: =SRI_LosRios!A7 -> G3 Alimentos y bebidas (agroindustria) | B7: =SRI_LosRios!D7 -> 93 | C7: =Supuestos!$B$8 -> 0.3 | D7: =B7*C7 -> 27.9 | E7: =D7*Supuestos!B15 -> 1.395 | F7: =D7*Supuestos!C15 -> 1.953 | G7: =D7*Supuestos!D15 -> 2.79 | H7: =D7*Supuestos!E15 -> 3.906 | I7: =D7*Supuestos!F15 -> 5.022 | J7: =D7*Supuestos!G15 -> 6.696
A8: =SRI_LosRios!A8 -> G4 Otras manufacturas | B8: =SRI_LosRios!D8 -> 163 | C8: =Supuestos!$B$8 -> 0.3 | D8: =B8*C8 -> 48.9 | E8: =D8*Supuestos!B16 -> 1.956 | F8: =D8*Supuestos!C16 -> 2.445 | G8: =D8*Supuestos!D16 -> 3.912 | H8: =D8*Supuestos!E16 -> 5.379 | I8: =D8*Supuestos!F16 -> 7.335 | J8: =D8*Supuestos!G16 -> 9.78
A9: =SRI_LosRios!A9 -> G5 Energía, agua y saneamiento | B9: =SRI_LosRios!D9 -> 97 | C9: =Supuestos!$B$8 -> 0.3 | D9: =B9*C9 -> 29.1 | E9: =D9*Supuestos!B17 -> 1.455 | F9: =D9*Supuestos!C17 -> 2.037 | G9: =D9*Supuestos!D17 -> 2.91 | H9: =D9*Supuestos!E17 -> 4.074 | I9: =D9*Supuestos!F17 -> 5.82 | J9: =D9*Supuestos!G17 -> 7.566
A10: =SRI_LosRios!A10 -> G6 Transporte y almacenamiento | B10: =SRI_LosRios!D10 -> 507 | C10: =Supuestos!$B$8 -> 0.3 | D10: =B10*C10 -> 152.1 | E10: =D10*Supuestos!B18 -> 3.042 | F10: =D10*Supuestos!C18 -> 4.563 | G10: =D10*Supuestos!D18 -> 7.605 | H10: =D10*Supuestos!E18 -> 10.647 | I10: =D10*Supuestos!F18 -> 15.21 | J10: =D10*Supuestos!G18 -> 21.294
A11: =SRI_LosRios!A11 -> G7 Comercio al por mayor | B11: =SRI_LosRios!D11 -> 1067 | C11: =Supuestos!$B$8 -> 0.3 | D11: =B11*C11 -> 320.1 | E11: =D11*Supuestos!B19 -> 1.6005 | F11: =D11*Supuestos!C19 -> 2.40075 | G11: =D11*Supuestos!D19 -> 4.8015 | H11: =D11*Supuestos!E19 -> 6.402 | I11: =D11*Supuestos!F19 -> 9.603 | J11: =D11*Supuestos!G19 -> 12.804
A12: =SRI_LosRios!A12 -> G8 Administración pública (GAD y entidades) | B12: =SRI_LosRios!D12 -> 96 | C12: =Supuestos!$B$9 -> 1 | D12: =B12*C12 -> 96 | E12: =D12*Supuestos!B20 -> 9.6 | F12: =D12*Supuestos!C20 -> 14.4 | G12: =D12*Supuestos!D20 -> 24 | H12: =D12*Supuestos!E20 -> 33.6 | I12: =D12*Supuestos!F20 -> 38.4 | J12: =D12*Supuestos!G20 -> 52.8
A13: =SRI_LosRios!A13 -> G9 Proveedores tecnológicos (TIC, ingeniería, I+D) | B13: =SRI_LosRios!D13 -> 257 | C13: =Supuestos!$B$8 -> 0.3 | D13: =B13*C13 -> 77.1 | E13: =D13*Supuestos!B21 -> 11.565 | F13: =D13*Supuestos!C21 -> 15.42 | G13: =D13*Supuestos!D21 -> 23.13 | H13: =D13*Supuestos!E21 -> 30.84 | I13: =D13*Supuestos!F21 -> 38.55 | J13: =D13*Supuestos!G21 -> 46.26
A14: Total empresas que adoptan | B14: =SUM(B5:B13) -> 3691 | D14: =SUM(D5:D13) -> 1174.5 | E14: =SUM(E5:E13) -> 34.8885 | F14: =SUM(F5:F13) -> 49.63125 | G14: =SUM(G5:G13) -> 79.836 | H14: =SUM(H5:H13) -> 109.8105 | I14: =SUM(I5:I13) -> 141.315 | J14: =SUM(J5:J13) -> 187.125
A16: Puestos de perfil IoT (stock acumulado)
A17: Escenario | B17: A 4 años (2030) | C17: A 5 años (2031) | D17: Promedio anual nuevo 2027-2031
A18: Conservador | B18: =E14*Supuestos!B26-Supuestos!$B$27 -> 34.8885 | C18: =F14*Supuestos!B26-Supuestos!$B$27 -> 49.63125 | D18: =C18/5 -> 9.92625
A19: Base | B19: =G14*Supuestos!C26-Supuestos!$B$27 -> 119.754 | C19: =H14*Supuestos!C26-Supuestos!$B$27 -> 164.71575 | D19: =C19/5 -> 32.94315
A20: Optimista | B20: =I14*Supuestos!D26-Supuestos!$B$27 -> 282.63 | C20: =J14*Supuestos!D26-Supuestos!$B$27 -> 374.25 | D20: =C20/5 -> 74.85
A22: Por grupo, escenario base 2031 (puestos)
A23: Grupo | B23: Puestos base 2031 | C23: % del total
A24: =A5 -> G1 Agricultura, ganadería y silvicultura | B24: =H5*Supuestos!$C$26 -> 22.00275 | C24: =B24/SUM($B$24:$B$32) -> 0.13358012
A25: =A6 -> G2 Pesca y acuicultura | B25: =H6*Supuestos!$C$26 -> 0.441 | C25: =B25/SUM($B$24:$B$32) -> 0.0026773396
A26: =A7 -> G3 Alimentos y bebidas (agroindustria) | B26: =H7*Supuestos!$C$26 -> 5.859 | C26: =B26/SUM($B$24:$B$32) -> 0.035570369
A27: =A8 -> G4 Otras manufacturas | B27: =H8*Supuestos!$C$26 -> 8.0685 | C27: =B27/SUM($B$24:$B$32) -> 0.048984387
A28: =A9 -> G5 Energía, agua y saneamiento | B28: =H9*Supuestos!$C$26 -> 6.111 | C28: =B28/SUM($B$24:$B$32) -> 0.037100277
A29: =A10 -> G6 Transporte y almacenamiento | B29: =H10*Supuestos!$C$26 -> 15.9705 | C29: =B29/SUM($B$24:$B$32) -> 0.096957941
A30: =A11 -> G7 Comercio al por mayor | B30: =H11*Supuestos!$C$26 -> 9.603 | C30: =B30/SUM($B$24:$B$32) -> 0.058300436
A31: =A12 -> G8 Administración pública (GAD y entidades) | B31: =H12*Supuestos!$C$26 -> 50.4 | C31: =B31/SUM($B$24:$B$32) -> 0.30598167
A32: =A13 -> G9 Proveedores tecnológicos (TIC, ingeniería, I+D) | B32: =H13*Supuestos!$C$26 -> 46.26 | C32: =B32/SUM($B$24:$B$32) -> 0.28084746

Sheet Oferta
A1: Oferta de profesionales con perfil IoT en Los Ríos
A2: Sin la carrera: graduados TIC de IES de Los Ríos con competencias IoT. Con la carrera: se suma su promoción desde el primer año de graduación.
A4: Concepto | B4: Oferta baja | C4: Oferta base | D4: Oferta alta
A5: Graduados TIC por año en IES de Los Ríos | B5: =Supuestos!B33 -> 69 | C5: =Supuestos!C33 -> 156 | D5: =Supuestos!D33 -> 255
A6: % con competencias útiles para IoT | B6: =Supuestos!B35 -> 0.02 | C6: =Supuestos!C35 -> 0.05 | D6: =Supuestos!D35 -> 0.1
A7: Graduados con perfil IoT por año (sin la carrera) | B7: =B5*B6 -> 1.38 | C7: =C5*C6 -> 7.8 | D7: =D5*D6 -> 25.5
A9: Acumulado de graduados con perfil IoT sin la carrera
A10: Período | B10: Oferta baja | C10: Oferta base | D10: Oferta alta
A11: 2027-2030 (4 años) | B11: =B7*4 -> 5.52 | C11: =C7*4 -> 31.2 | D11: =D7*4 -> 102
A12: 2027-2031 (5 años) | B12: =B7*5 -> 6.9 | C12: =C7*5 -> 39 | D12: =D7*5 -> 127.5
A14: Graduados de la carrera propuesta
A15: Concepto | B15: Valor
A16: Primer año de graduación | B16: =Supuestos!B40+Supuestos!B41 -> 2031
A17: Graduados por promoción | B17: =Supuestos!B38*Supuestos!B39 -> 24.384
A18: Graduados acumulados hasta 2030 | B18: =MAX(0,2030-B16+1)*B17 -> 0
A19: Graduados acumulados hasta 2031 | B19: =MAX(0,2031-B16+1)*B17 -> 24.384
A20: Graduados por año desde el segundo año de graduación | B20: =B17 -> 24.384

Sheet Brecha
A1: Brecha entre demanda y oferta de perfiles IoT en Los Ríos
A2: Brecha = puestos demandados − graduados con perfil IoT disponibles. Positiva: faltan profesionales.
A4: Horizonte A 4 años (2030)
A5: Sin la carrera
A6: Demanda \ Oferta | B6: Oferta baja | C6: Oferta base | D6: Oferta alta
A7: Demanda conservador | B7: =Demanda!B18-Oferta!B11 -> 29.3685 | C7: =Demanda!B18-Oferta!C11 -> 3.6885 | D7: =Demanda!B18-Oferta!D11 -> -67.1115
A8: Demanda base | B8: =Demanda!B19-Oferta!B11 -> 114.234 | C8: =Demanda!B19-Oferta!C11 -> 88.554 | D8: =Demanda!B19-Oferta!D11 -> 17.754
A9: Demanda optimista | B9: =Demanda!B20-Oferta!B11 -> 277.11 | C9: =Demanda!B20-Oferta!C11 -> 251.43 | D9: =Demanda!B20-Oferta!D11 -> 180.63
A11: Con la carrera
A12: Demanda \ Oferta | B12: Oferta baja | C12: Oferta base | D12: Oferta alta
A13: Demanda conservador | B13: =Demanda!B18-Oferta!B11-Oferta!B18 -> 29.3685 | C13: =Demanda!B18-Oferta!C11-Oferta!B18 -> 3.6885 | D13: =Demanda!B18-Oferta!D11-Oferta!B18 -> -67.1115
A14: Demanda base | B14: =Demanda!B19-Oferta!B11-Oferta!B18 -> 114.234 | C14: =Demanda!B19-Oferta!C11-Oferta!B18 -> 88.554 | D14: =Demanda!B19-Oferta!D11-Oferta!B18 -> 17.754
A15: Demanda optimista | B15: =Demanda!B20-Oferta!B11-Oferta!B18 -> 277.11 | C15: =Demanda!B20-Oferta!C11-Oferta!B18 -> 251.43 | D15: =Demanda!B20-Oferta!D11-Oferta!B18 -> 180.63
A18: Horizonte A 5 años (2031)
A19: Sin la carrera
A20: Demanda \ Oferta | B20: Oferta baja | C20: Oferta base | D20: Oferta alta
A21: Demanda conservador | B21: =Demanda!C18-Oferta!B12 -> 42.73125 | C21: =Demanda!C18-Oferta!C12 -> 10.63125 | D21: =Demanda!C18-Oferta!D12 -> -77.86875
A22: Demanda base | B22: =Demanda!C19-Oferta!B12 -> 157.81575 | C22: =Demanda!C19-Oferta!C12 -> 125.71575 | D22: =Demanda!C19-Oferta!D12 -> 37.21575
A23: Demanda optimista | B23: =Demanda!C20-Oferta!B12 -> 367.35 | C23: =Demanda!C20-Oferta!C12 -> 335.25 | D23: =Demanda!C20-Oferta!D12 -> 246.75
A25: Con la carrera
A26: Demanda \ Oferta | B26: Oferta baja | C26: Oferta base | D26: Oferta alta
A27: Demanda conservador | B27: =Demanda!C18-Oferta!B12-Oferta!B19 -> 18.34725 | C27: =Demanda!C18-Oferta!C12-Oferta!B19 -> -13.75275 | D27: =Demanda!C18-Oferta!D12-Oferta!B19 -> -102.25275
A28: Demanda base | B28: =Demanda!C19-Oferta!B12-Oferta!B19 -> 133.43175 | C28: =Demanda!C19-Oferta!C12-Oferta!B19 -> 101.33175 | D28: =Demanda!C19-Oferta!D12-Oferta!B19 -> 12.83175
A29: Demanda optimista | B29: =Demanda!C20-Oferta!B12-Oferta!B19 -> 342.966 | C29: =Demanda!C20-Oferta!C12-Oferta!B19 -> 310.866 | D29: =Demanda!C20-Oferta!D12-Oferta!B19 -> 222.366
A32: Flujo anual en régimen (desde 2032, con la carrera funcionando)
A33: Escenario | B33: Puestos nuevos por año | C33: Graduados IoT por año sin la carrera (oferta base) | D33: Graduados por año de la carrera | E33: Cobertura sin la carrera | F33: Cobertura con la carrera
A34: Conservador | B34: =Demanda!D18 -> 9.92625 | C34: =Oferta!C7 -> 7.8 | D34: =Oferta!B20 -> 24.384 | E34: =C34/B34 -> 0.78579524 | F34: =(C34+D34)/B34 -> 3.2423121
A35: Base | B35: =Demanda!D19 -> 32.94315 | C35: =Oferta!C7 -> 7.8 | D35: =Oferta!B20 -> 24.384 | E35: =C35/B35 -> 0.23677153 | F35: =(C35+D35)/B35 -> 0.97695576
A36: Optimista | B36: =Demanda!D20 -> 74.85 | C36: =Oferta!C7 -> 7.8 | D36: =Oferta!B20 -> 24.384 | E36: =C36/B36 -> 0.10420842 | F36: =(C36+D36)/B36 -> 0.42997996
A37: Cobertura mayor a 100 %: la oferta supera los puestos nuevos, lo que sería sobreoferta.

Sheet Sensibilidad
A1: Sensibilidad de la demanda a 5 años (2031)
A2: Puestos IoT si la adopción base se multiplica por un factor y cambia el número de profesionales por empresa adoptante.
A4: Empresas que adoptan en 2031, escenario base | B4: =Demanda!H14 -> 109.8105
A6: Multiplicador de adopción \ profesionales por empresa | B6: 1 | C6: 1.5 | D6: 2 | E6: 3
A7: 0.25 | B7: =$B$4*$A7*B$6 -> 27.452625 | C7: =$B$4*$A7*C$6 -> 41.178937 | D7: =$B$4*$A7*D$6 -> 54.90525 | E7: =$B$4*$A7*E$6 -> 82.357875
A8: 0.5 | B8: =$B$4*$A8*B$6 -> 54.90525 | C8: =$B$4*$A8*C$6 -> 82.357875 | D8: =$B$4*$A8*D$6 -> 109.8105 | E8: =$B$4*$A8*E$6 -> 164.71575
A9: 1 | B9: =$B$4*$A9*B$6 -> 109.8105 | C9: =$B$4*$A9*C$6 -> 164.71575 | D9: =$B$4*$A9*D$6 -> 219.621 | E9: =$B$4*$A9*E$6 -> 329.4315
A10: 1.5 | B10: =$B$4*$A10*B$6 -> 164.71575 | C10: =$B$4*$A10*C$6 -> 247.07362 | D10: =$B$4*$A10*D$6 -> 329.4315 | E10: =$B$4*$A10*E$6 -> 494.14725
A11: 2 | B11: =$B$4*$A11*B$6 -> 219.621 | C11: =$B$4*$A11*C$6 -> 329.4315 | D11: =$B$4*$A11*D$6 -> 439.242 | E11: =$B$4*$A11*E$6 -> 658.863
A13: Lectura: la fila 1,00x y la columna 1,5 reproducen el escenario base. Compare con los graduados por año de la hoja Brecha.

Sheet Muestra
A1: Marco muestral y asignación de la encuesta a empleadores
A2: Marco: empresas formales de los grupos G1 a G9 del catastro RUC del SRI. Asignación proporcional por grupo con un mínimo por estrato.
A4: Población N (empresas formales G1 a G9) | B4: =SRI_LosRios!D5+SRI_LosRios!D6+SRI_LosRios!D7+SRI_LosRios!D8+SRI_LosRios!D9+SRI_LosRios!D10+SRI_LosRios!D11+SRI_LosRios!D12+SRI_LosRios!D13 -> 3691
A5: Nivel de confianza (z) | B5: 1.96
A6: Error máximo (e) | B6: 0.05
A7: Proporción esperada (p) | B7: 0.5
A8: Tamaño de muestra n | B8: =ROUNDUP(B4*B5^2*B7*(1-B7)/(B6^2*(B4-1)+B5^2*B7*(1-B7)),0) -> 349
A9: Mínimo por estrato | B9: 10
A11: Grupo (estrato) | B11: Empresas formales Nh | C11: Muestra proporcional | D11: Muestra con mínimo
A12: =SRI_LosRios!A5 -> G1 Agricultura, ganadería y silvicultura | B12: =SRI_LosRios!D5 -> 1397 | C12: =$B$8*B12/$B$4 -> 132.09239 | D12: =MIN(B12,MAX($B$9,ROUND(C12,0))) -> 132
A13: =SRI_LosRios!A6 -> G2 Pesca y acuicultura | B13: =SRI_LosRios!D6 -> 14 | C13: =$B$8*B13/$B$4 -> 1.3237605 | D13: =MIN(B13,MAX($B$9,ROUND(C13,0))) -> 10
A14: =SRI_LosRios!A7 -> G3 Alimentos y bebidas (agroindustria) | B14: =SRI_LosRios!D7 -> 93 | C14: =$B$8*B14/$B$4 -> 8.7935519 | D14: =MIN(B14,MAX($B$9,ROUND(C14,0))) -> 10
A15: =SRI_LosRios!A8 -> G4 Otras manufacturas | B15: =SRI_LosRios!D8 -> 163 | C15: =$B$8*B15/$B$4 -> 15.412354 | D15: =MIN(B15,MAX($B$9,ROUND(C15,0))) -> 15
A16: =SRI_LosRios!A9 -> G5 Energía, agua y saneamiento | B16: =SRI_LosRios!D9 -> 97 | C16: =$B$8*B16/$B$4 -> 9.1717692 | D16: =MIN(B16,MAX($B$9,ROUND(C16,0))) -> 10
A17: =SRI_LosRios!A10 -> G6 Transporte y almacenamiento | B17: =SRI_LosRios!D10 -> 507 | C17: =$B$8*B17/$B$4 -> 47.939041 | D17: =MIN(B17,MAX($B$9,ROUND(C17,0))) -> 48
A18: =SRI_LosRios!A11 -> G7 Comercio al por mayor | B18: =SRI_LosRios!D11 -> 1067 | C18: =$B$8*B18/$B$4 -> 100.88946 | D18: =MIN(B18,MAX($B$9,ROUND(C18,0))) -> 101
A19: =SRI_LosRios!A12 -> G8 Administración pública (GAD y entidades) | B19: =SRI_LosRios!D12 -> 96 | C19: =$B$8*B19/$B$4 -> 9.0772148 | D19: =MIN(B19,MAX($B$9,ROUND(C19,0))) -> 10
A20: =SRI_LosRios!A13 -> G9 Proveedores tecnológicos (TIC, ingeniería, I+D) | B20: =SRI_LosRios!D13 -> 257 | C20: =$B$8*B20/$B$4 -> 24.300461 | D20: =MIN(B20,MAX($B$9,ROUND(C20,0))) -> 24
A21: Total | B21: =SUM(B12:B20) -> 3691 | C21: =SUM(C12:C20) -> 349 | D21: =SUM(D12:D20) -> 360
A23: Los estratos pequeños se encuestan casi completos (censo) por el mínimo; por eso el total con mínimo supera a n. Se recomienda además estratificar por cantón con las cifras de la hoja SRI_LosRios.
